main/test_files/test-f1-2.txt
50000
sell 129
buy 69
sell 85
buy 61
sell 124
buy 69
sell 129
buy 81
sell 90
buy 51
sell 107
buy 53
sell 104
buy 90
sell 130
buy 87
sell 125
buy 78
sell 94
buy 66
sell 98
buy 54
sell 108
buy 85
sell 111
buy 93
sell 87
buy 93
sell 121
buy 94
sell 100
buy 70
sell 116
buy 91
sell 93
buy 73
sell 117
buy 67
sell 87
buy 88
sell 98
buy 54
sell 99
buy 90
sell 117
buy 60
sell 89
buy 99
sell 113
buy 69
sell 128
buy 72
sell 110
buy 69
sell 112
buy 51
sell 95
buy 96
sell 99
buy 61
sell 114
buy 57
sell 114
buy 60
sell 104
buy 56
sell 86
buy 85
sell 130
buy 85
sell 87
buy 62
sell 89
buy 95
sell 81
buy 50
sell 122
buy 67
sell 83
buy 99
sell 126
buy 95
sell 88
buy 68
sell 112
buy 99
sell 125
buy 80
sell 102
buy 63
sell 112
buy 69
sell 116
buy 88
sell 120
buy 78
sell 106
buy 81
sell 117
buy 99
sell 99
buy 93
sell 126
buy 70
sell 87
buy 88
sell 94
buy 82
sell 114
buy 83
sell 123
buy 71
sell 102
buy 100
sell 87
buy 64
sell 97
buy 98
sell 116
buy 90
sell 117
buy 57
sell 84
buy 61
sell 127
buy 72
sell 112
buy 53
sell 93
buy 68
sell 130
buy 51
sell 96
buy 60
sell 109
buy 98
sell 107
buy 87
sell 117
buy 95
sell 106
buy 99
sell 100
buy 98
sell 94
buy 63
sell 99
buy 99
sell 109
buy 56
sell 115
buy 67
sell 127
buy 89
sell 112
buy 60
sell 88
buy 96
sell 98
buy 100
sell 120
buy 82
sell 107
buy 56
sell 124
buy 65
sell 103
buy 84
sell 119
buy 96
sell 99
buy 81
sell 111
buy 54
sell 100
buy 87
sell 99
buy 56
sell 129
buy 50
sell 124
buy 61
sell 103
buy 88
sell 129
buy 86
sell 105
buy 67
sell 95
buy 85
sell 122
buy 99
sell 122
buy 71
sell 98
buy 85
sell 123
buy 52
sell 122
buy 60
sell 121
buy 50
sell 82
buy 97
sell 94
buy 73
sell 124
buy 87
sell 87
buy 98
sell 95
buy 57
sell 89
buy 64
sell 109
buy 91
sell 86
buy 72
sell 93
buy 76
sell 113
buy 78
sell 108
buy 100
sell 105
buy 100
sell 97
buy 71
sell 82
buy 100
sell 95
buy 92
sell 103
buy 100
sell 94
buy 56
sell 105
buy 92
sell 109
buy 86
sell 115
buy 83
sell 106
buy 52
sell 114
buy 72
sell 115
buy 73
sell 89
buy 85
sell 95
buy 95
sell 95
buy 63
sell 93
buy 89
sell 129
buy 59
sell 120
buy 77
sell 84
buy 54
sell 82
buy 50
sell 128
buy 60
sell 121
buy 59
sell 124
buy 56
sell 103
buy 84
sell 113
buy 66
sell 91
buy 54
sell 130
buy 57
sell 84
buy 56
sell 90
buy 92
sell 105
buy 79
sell 100
buy 59
sell 88
buy 79
sell 119
buy 60
sell 91
buy 52
sell 97
buy 87
sell 90
buy 57
sell 107
buy 80
sell 121
buy 87
sell 123
buy 76
sell 118
buy 86
sell 128
buy 91
sell 110
buy 81
sell 103
buy 65
sell 81
buy 94
sell 130
buy 71
sell 108
buy 77
sell 100
buy 88
sell 119
buy 51
sell 84
buy 93
sell 106
buy 97
sell 83
buy 74
sell 97
buy 98
sell 118
buy 50
sell 100
buy 77
sell 80
buy 55
sell 90
buy 60
sell 91
buy 64
sell 112
buy 92
sell 115
buy 74
sell 130
buy 55
sell 87
buy 57
sell 96
buy 65
sell 96
buy 88
sell 103
buy 56
sell 110
buy 91
sell 106
buy 100
sell 109
buy 54
sell 104
buy 91
sell 89
buy 86
sell 91
buy 91
sell 80
buy 70
sell 82
buy 71
sell 121
buy 91
sell 112
buy 56
sell 101
buy 93
sell 104
buy 85
sell 108
buy 83
sell 123
buy 88
sell 88
buy 92
sell 128
buy 65
sell 89
buy 70
sell 119
buy 63
sell 97
buy 63
sell 116
buy 82
sell 124
buy 60
sell 98
buy 73
sell 107
buy 75
sell 106
buy 86
sell 82
buy 85
sell 108
buy 84
sell 92
buy 71
sell 108
buy 80
sell 106
buy 70
sell 116
buy 66
sell 92
buy 76
sell 102
buy 89
sell 126
buy 73
sell 108
buy 95
sell 130
buy 75
sell 115
buy 88
sell 89
buy 66
sell 95
buy 50
sell 111
buy 83
sell 113
buy 60
sell 120
buy 94
sell 82
buy 78
sell 111
buy 85
sell 94
buy 69
sell 120
buy 52
sell 119
buy 50
sell 87
buy 64
sell 97
buy 51
sell 111
buy 88
sell 121
buy 58
sell 96
buy 100
sell 113
buy 64
sell 98
buy 76
sell 110
buy 84
sell 118
buy 100
sell 113
buy 57
sell 88
buy 60
sell 103
buy 54
sell 123
buy 79
sell 123
buy 60
sell 110
buy 57
sell 120
buy 53
sell 125
buy 53
sell 92
buy 95
sell 104
buy 56
sell 104
buy 69
sell 90
buy 90
sell 84
buy 61
sell 106
buy 71
sell 113
buy 54
sell 112
buy 83
sell 103
buy 67
sell 100
buy 59
sell 85
buy 55
sell 88
buy 53
sell 105
buy 98
sell 110
buy 76
sell 118
buy 66
sell 87
buy 82
sell 85
buy 81
sell 123
buy 65
sell 96
buy 72
sell 91
buy 94
sell 96
buy 60
sell 109
buy 86
sell 105
buy 67
sell 88
buy 98
sell 119
buy 66
sell 86
buy 94
sell 96
buy 100
sell 93
buy 67
sell 126
buy 99
sell 85
buy 68
sell 87
buy 51
sell 127
buy 62
sell 82
buy 85
sell 130
buy 52
sell 93
buy 76
sell 106
buy 62
sell 84
buy 99
sell 84
buy 74
sell 106
buy 95
sell 130
buy 73
sell 85
buy 89
sell 90
buy 78
sell 113
buy 72
sell 127
buy 92
sell 98
buy 76
sell 128
buy 59
sell 92
buy 67
sell 96
buy 57
sell 92
buy 88
sell 84
buy 86
sell 124
buy 92
sell 106
buy 91
sell 123
buy 81
sell 112
buy 62
sell 88
buy 90
sell 124
buy 68
sell 101
buy 80
sell 89
buy 95
sell 93
buy 76
sell 94
buy 76
sell 124
buy 78
sell 98
buy 75
sell 92
buy 63
sell 88
buy 97
sell 89
buy 90
sell 83
buy 89
sell 83
buy 95
sell 94
buy 89
sell 97
buy 78
sell 127
buy 69
sell 82
buy 99
sell 90
buy 75
sell 111
buy 65
sell 96
buy 61
sell 80
buy 94
sell 128
buy 72
sell 114
buy 82
sell 123
buy 94
sell 127
buy 55
sell 82
buy 61
sell 102
buy 93
sell 117
buy 67
sell 112
buy 89
sell 84
buy 58
sell 114
buy 71
sell 112
buy 88
sell 104
buy 99
sell 92
buy 68
sell 123
buy 76
sell 92
buy 73
sell 92
buy 56
sell 102
buy 52
sell 105
buy 79
sell 127
buy 80
sell 118
buy 60
sell 116
buy 87
sell 125
buy 85
sell 97
buy 77
sell 121
buy 77
sell 119
buy 53
sell 95
buy 89
sell 86
buy 75
sell 110
buy 54
sell 118
buy 65
sell 102
buy 53
sell 130
buy 79
sell 129
buy 74
sell 97
buy 91
sell 99
buy 94
sell 105
buy 78
sell 95
buy 89
sell 87
buy 57
sell 121
buy 97
sell 109
buy 57
sell 97
buy 88
sell 93
buy 72
sell 96
buy 65
sell 101
buy 57
sell 104
buy 61
sell 86
buy 86
sell 106
buy 65
sell 88
buy 98
sell 96
buy 55
sell 99
buy 96
sell 125
buy 51
sell 108
buy 85
sell 86
buy 58
sell 98
buy 54
sell 115
buy 96
sell 111
buy 81
sell 102
buy 69
sell 114
buy 52
sell 87
buy 64
sell 98
buy 94
sell 118
buy 88
sell 120
buy 93
sell 107
buy 78
sell 121
buy 65
sell 94
buy 87
sell 90
buy 99
sell 104
buy 58
sell 83
buy 61
sell 112
buy 73
sell 82
buy 53
sell 121
buy 89
sell 103
buy 79
sell 81
buy 68
sell 81
buy 57
sell 111
buy 90
sell 120
buy 66
sell 107
buy 51
sell 91
buy 62
sell 90
buy 78
sell 118
buy 100
sell 106
buy 80
sell 125
buy 69
sell 121
buy 97
sell 119
buy 75
sell 103
buy 53
sell 123
buy 99
sell 125
buy 92
sell 107
buy 68
sell 109
buy 94
sell 111
buy 97
sell 119
buy 66
sell 109
buy 89
sell 106
buy 90
sell 87
buy 65
sell 83
buy 52
sell 85
buy 80
sell 111
buy 92
sell 87
buy 63
sell 88
buy 55
sell 89
buy 77
sell 93
buy 62
sell 108
buy 62
sell 117
buy 73
sell 122
buy 96
sell 86
buy 83
sell 82
buy 96
sell 99
buy 51
sell 107
buy 97
sell 84
buy 79
sell 108
buy 64
sell 107
buy 67
sell 119
buy 60
sell 110
buy 73
sell 128
buy 55
sell 113
buy 96
sell 100
buy 60
sell 118
buy 87
sell 115
buy 91
sell 91
buy 66
sell 98
buy 67
sell 111
buy 78
sell 97
buy 100
sell 81
buy 53
sell 127
buy 89
sell 115
buy 100
sell 128
buy 91
sell 83
buy 100
sell 114
buy 98
sell 117
buy 98
sell 124
buy 70
sell 109
buy 84
sell 83
buy 64
sell 123
buy 87
sell 108
buy 84
sell 80
buy 61
sell 130
buy 98
sell 114
buy 56
sell 107
buy 56
sell 97
buy 87
sell 86
buy 68
sell 80
buy 80
sell 126
buy 61
sell 115
buy 82
sell 97
buy 87
sell 82
buy 76
sell 88
buy 82
sell 99
buy 84
sell 109
buy 76
sell 124
buy 64
sell 126
buy 50
sell 117
buy 88
sell 130
buy 91
sell 82
buy 57
sell 129
buy 91
sell 87
buy 70
sell 117
buy 96
sell 117
buy 92
sell 99
buy 67
sell 107
buy 57
sell 84
buy 55
sell 95
buy 86
sell 127
buy 93
sell 84
buy 95
sell 93
buy 57
sell 89
buy 80
sell 122
buy 91
sell 87
buy 76
sell 121
buy 72
sell 103
buy 76
sell 103
buy 56
sell 106
buy 70
sell 124
buy 87
sell 107
buy 52
sell 127
buy 84
sell 112
buy 90
sell 97
buy 62
sell 113
buy 81
sell 95
buy 51
sell 115
buy 51
sell 89
buy 96
sell 95
buy 73
sell 123
buy 69
sell 121
buy 89
sell 129
buy 78
sell 85
buy 90
sell 86
buy 79
sell 127
buy 69
sell 115
buy 73
sell 115
buy 62
sell 125
buy 100
sell 114
buy 91
sell 122
buy 82
sell 130
buy 86
sell 84
buy 94
sell 88
buy 84
sell 103
buy 51
sell 116
buy 97
sell 87
buy 57
sell 88
buy 59
