main/test_files/test-f1-3.txt
200000
sell 101
buy 96
sell 102
buy 61
sell 90
buy 71
sell 102
buy 72
sell 113
buy 100
sell 102
buy 55
sell 82
buy 50
sell 96
buy 85
sell 114
buy 78
sell 117
buy 59
sell 127
buy 99
sell 90
buy 81
sell 102
buy 65
sell 100
buy 85
sell 114
buy 83
sell 107
buy 60
sell 104
buy 74
sell 85
buy 84
sell 124
buy 92
sell 89
buy 90
sell 119
buy 87
sell 126
buy 77
sell 87
buy 85
sell 130
buy 97
sell 113
buy 74
sell 123
buy 60
sell 123
buy 66
sell 98
buy 54
sell 124
buy 63
sell 119
buy 86
sell 102
buy 50
sell 107
buy 87
sell 93
buy 74
sell 89
buy 56
sell 84
buy 62
sell 104
buy 87
sell 114
buy 72
sell 127
buy 75
sell 94
buy 62
sell 91
buy 97
sell 93
buy 97
sell 103
buy 70
sell 84
buy 93
sell 107
buy 56
sell 100
buy 76
sell 117
buy 96
sell 121
buy 58
sell 87
buy 83
sell 110
buy 65
sell 82
buy 67
sell 118
buy 60
sell 125
buy 62
sell 107
buy 95
sell 121
buy 71
sell 125
buy 74
sell 126
buy 87
sell 107
buy 98
sell 107
buy 92
sell 88
buy 57
sell 89
buy 79
sell 123
buy 79
sell 129
buy 85
sell 97
buy 69
sell 95
buy 61
sell 91
buy 99
sell 95
buy 96
sell 101
buy 90
sell 88
buy 93
sell 80
buy 66
sell 89
buy 73
sell 84
buy 72
sell 110
buy 85
sell 108
buy 79
sell 124
buy 63
sell 93
buy 94
sell 116
buy 99
sell 108
buy 73
sell 115
buy 69
sell 95
buy 61
sell 92
buy 68
sell 92
buy 59
sell 97
buy 61
sell 117
buy 60
sell 100
buy 85
sell 94
buy 64
sell 122
buy 79
sell 120
buy 68
sell 83
buy 58
sell 96
buy 70
sell 102
buy 75
sell 80
buy 66
sell 95
buy 94
sell 90
buy 77
sell 93
buy 58
sell 114
buy 81
sell 99
buy 51
sell 100
buy 85
sell 129
buy 97
sell 128
buy 61
sell 89
buy 64
sell 90
buy 54
sell 99
buy 61
sell 127
buy 63
sell 99
buy 55
sell 96
buy 90
sell 106
buy 94
sell 127
buy 98
sell 87
buy 63
sell 117
buy 65
sell 116
buy 83
sell 100
buy 91
sell 109
buy 79
sell 92
buy 59
sell 96
buy 69
sell 112
buy 59
sell 80
buy 51
sell 115
buy 97
sell 112
buy 51
sell 108
buy 80
sell 80
buy 54
sell 115
buy 70
sell 81
buy 92
sell 100
buy 94
sell 110
buy 62
sell 127
buy 56
sell 82
buy 56
sell 95
buy 54
sell 82
buy 57
sell 95
buy 75
sell 118
buy 81
sell 101
buy 79
sell 105
buy 93
sell 102
buy 69
sell 83
buy 51
sell 81
buy 75
sell 129
buy 95
sell 127
buy 72
sell 101
buy 63
sell 109
buy 84
sell 89
buy 82
sell 95
buy 61
sell 113
buy 69
sell 103
buy 84
sell 102
buy 64
sell 98
buy 75
sell 130
buy 92
sell 101
buy 99
sell 90
buy 70
sell 95
buy 87
sell 109
buy 64
sell 90
buy 99
sell 128
buy 80
sell 112
buy 79
sell 100
buy 92
sell 92
buy 50
sell 113
buy 75
sell 92
buy 98
sell 94
buy 60
sell 126
buy 86
sell 102
buy 52
sell 122
buy 68
sell 113
buy 64
sell 93
buy 72
sell 118
buy 92
sell 96
buy 60
sell 111
buy 81
sell 110
buy 60
sell 82
buy 80
sell 99
buy 64
sell 122
buy 95
sell 115
buy 60
sell 124
buy 69
sell 102
buy 73
sell 81
buy 60
sell 106
buy 66
sell 91
buy 66
sell 89
buy 81
sell 106
buy 51
sell 109
buy 65
sell 115
buy 96
sell 112
buy 64
sell 123
buy 57
sell 83
buy 71
sell 103
buy 66
sell 88
buy 66
sell 97
buy 58
sell 84
buy 87
sell 98
buy 55
sell 119
buy 84
sell 102
buy 65
sell 107
buy 83
sell 124
buy 99
sell 101
buy 63
sell 81
buy 65
sell 86
buy 74
sell 80
buy 85
sell 103
buy 78
sell 123
buy 53
sell 128
buy 72
sell 121
buy 53
sell 84
buy 79
sell 105
buy 66
sell 108
buy 69
sell 88
buy 79
sell 118
buy 92
sell 112
buy 86
sell 105
buy 54
sell 109
buy 89
sell 103
buy 77
sell 125
buy 67
sell 80
buy 60
sell 92
buy 85
sell 119
buy 90
sell 96
buy 52
sell 126
buy 69
sell 96
buy 50
sell 83
buy 79
sell 117
buy 64
sell 111
buy 63
sell 84
buy 87
sell 129
buy 60
sell 107
buy 92
sell 105
buy 100
sell 86
buy 53
sell 125
buy 94
sell 107
buy 76
sell 91
buy 51
sell 100
buy 74
sell 127
buy 67
sell 124
buy 50
sell 127
buy 78
sell 111
buy 79
sell 124
buy 75
sell 90
buy 51
sell 88
buy 60
sell 88
buy 75
sell 82
buy 61
sell 88
buy 92
sell 105
buy 80
sell 94
buy 64
sell 96
buy 62
sell 130
buy 51
sell 95
buy 100
sell 113
buy 95
sell 103
buy 87
sell 126
buy 83
sell 114
buy 85
sell 127
buy 95
sell 91
buy 76
sell 87
buy 79
sell 101
buy 63
sell 83
buy 83
sell 101
buy 71
sell 97
buy 68
sell 112
buy 84
sell 84
buy 98
sell 99
buy 79
sell 98
buy 91
sell 82
buy 75
sell 117
buy 67
sell 82
buy 90
sell 123
buy 63
sell 80
buy 73
sell 95
buy 70
sell 100
buy 72
sell 118
buy 86
sell 96
buy 100
sell 102
buy 53
sell 106
buy 98
sell 95
buy 94
sell 91
buy 50
sell 119
buy 93
sell 124
buy 98
sell 119
buy 77
sell 82
buy 95
sell 123
buy 83
sell 95
buy 81
sell 95
buy 69
sell 112
buy 67
sell 123
buy 76
sell 117
buy 85
sell 114
buy 56
sell 100
buy 56
sell 118
buy 74
sell 95
buy 87
sell 121
buy 80
sell 125
buy 60
sell 123
buy 98
sell 91
buy 78
sell 115
buy 91
sell 87
buy 61
sell 88
buy 95
sell 123
buy 77
sell 82
buy 81
sell 101
buy 62
sell 90
buy 93
sell 92
buy 57
sell 112
buy 55
sell 90
buy 72
sell 126
buy 93
sell 116
buy 78
sell 120
buy 62
sell 113
buy 56
sell 89
buy 81
sell 99
buy 69
sell 87
buy 92
sell 124
buy 91
sell 123
buy 74
sell 117
buy 61
sell 113
buy 68
sell 128
buy 73
sell 94
buy 93
sell 124
buy 61
sell 130
buy 70
sell 80
buy 92
sell 93
buy 80
sell 126
buy 84
sell 87
buy 57
sell 87
buy 77
sell 91
buy 76
sell 117
buy 52
sell 116
buy 62
sell 126
buy 65
sell 103
buy 65
sell 85
buy 73
sell 92
buy 61
sell 85
buy 67
sell 128
buy 87
sell 86
buy 78
sell 97
buy 100
sell 80
buy 91
sell 81
buy 94
sell 88
buy 56
sell 126
buy 98
sell 103
buy 56
sell 130
buy 61
sell 91
buy 92
sell 122
buy 96
sell 116
buy 90
sell 92
buy 79
sell 91
buy 80
sell 103
buy 73
sell 110
buy 59
sell 114
buy 83
sell 120
buy 69
sell 96
buy 88
sell 81
buy 80
sell 102
buy 72
sell 112
buy 55
sell 81
buy 96
sell 91
buy 89
sell 116
buy 84
sell 110
buy 53
sell 119
buy 50
sell 95
buy 55
sell 128
buy 59
sell 90
buy 63
sell 111
buy 80
sell 80
buy 61
sell 86
buy 78
sell 124
buy 56
sell 101
buy 97
sell 114
buy 86
sell 127
buy 90
sell 105
buy 71
sell 82
buy 91
sell 85
buy 80
sell 126
buy 99
sell 85
buy 73
sell 81
buy 97
sell 92
buy 64
sell 87
buy 77
sell 123
buy 65
sell 117
buy 95
sell 103
buy 71
sell 121
buy 58
sell 129
buy 56
sell 96
buy 67
sell 117
buy 76
sell 126
buy 95
sell 127
buy 62
sell 91
buy 71
sell 119
buy 91
sell 129
buy 58
sell 102
buy 79
sell 82
buy 70
sell 125
buy 94
sell 129
buy 65
sell 81
buy 86
sell 112
buy 88
sell 121
buy 65
sell 121
buy 78
sell 128
buy 68
sell 106
buy 66
sell 105
buy 74
sell 118
buy 67
sell 100
buy 89
sell 130
buy 66
sell 119
buy 89
sell 120
buy 73
sell 84
buy 67
sell 114
buy 88
sell 87
buy 77
sell 83
buy 64
sell 80
buy 64
sell 92
buy 75
sell 86
buy 99
sell 104
buy 69
sell 108
buy 94
sell 125
buy 97
sell 122
buy 81
sell 86
buy 81
sell 117
buy 84
sell 118
buy 74
sell 91
buy 85
sell 80
buy 67
sell 126
buy 56
sell 103
buy 94
sell 98
buy 74
sell 106
buy 64
sell 112
buy 72
sell 82
buy 82
sell 114
buy 70
sell 102
buy 61
sell 83
buy 60
sell 98
buy 87
sell 90
buy 51
sell 105
buy 61
sell 115
buy 91
sell 86
buy 53
sell 102
buy 79
sell 103
buy 87
sell 107
buy 71
sell 98
buy 57
sell 86
buy 61
sell 128
buy 55
sell 113
buy 83
sell 129
buy 83
sell 88
buy 84
sell 113
buy 53
sell 92
buy 84
sell 93
buy 98
sell 101
buy 63
sell 99
buy 62
sell 92
buy 84
sell 109
buy 65
sell 102
buy 77
sell 102
buy 80
sell 80
buy 66
sell 121
buy 82
sell 80
buy 89
sell 106
buy 73
sell 93
buy 86
sell 108
buy 86
sell 86
buy 89
sell 113
buy 57
sell 90
buy 91
sell 80
buy 86
sell 93
buy 62
sell 87
buy 80
sell 123
buy 77
sell 96
buy 99
sell 106
buy 54
sell 109
buy 71
sell 80
buy 59
sell 109
buy 79
sell 107
buy 90
sell 83
buy 73
sell 127
buy 63
sell 106
buy 70
sell 118
buy 50
sell 81
buy 76
sell 88
buy 58
sell 102
buy 57
sell 96
buy 67
sell 99
buy 73
sell 90
buy 87
sell 83
buy 79
sell 105
buy 82
sell 114
buy 87
sell 101
buy 68
sell 121
buy 51
sell 90
buy 62
sell 125
buy 84
sell 96
buy 84
sell 115
buy 98
sell 104
buy 100
sell 110
buy 52
sell 86
buy 90
sell 107
buy 66
sell 129
buy 68
sell 125
buy 69
sell 102
buy 79
sell 92
buy 98
sell 97
buy 100
sell 109
buy 63
sell 116
buy 52
sell 102
buy 50
sell 86
buy 81
sell 102
buy 78
sell 80
buy 75
sell 85
buy 86
sell 121
buy 80
sell 97
buy 81
sell 86
buy 50
sell 100
buy 73
sell 113
buy 78
sell 96
buy 69
sell 90
buy 90
sell 127
buy 93
sell 99
buy 93
sell 108
buy 84
sell 84
buy 95
